Workbook

Sheet ORDERS
A1: Order_ID | B1: Order_Name | C1: Parity_Target | D1: Scope_Includes | E1: Feature_IDs | F1: Gate_Script_Path | G1: Gate_Command | H1: Evidence_Artifacts | I1: Pass_Criteria | J1: Depends_On_Orders | K1: Priority | L1: Estimated_Effort_Hours | M1: Status | N1: Owner | O1: Last_Updated_At | P1: Last_Updated_By | Q1: Notes | R1: Gate_Strength_Min | S1: Disallow_Stub | T1: Auto_Update_Excel | U1: Auto_Generated_Tests_Ref
A2: ORD-01 | B2: Auth parity (Login/OTP/Sessions) | C2: Urban Points Qatar Auth | D2: Phone login + OTP verify + session persistence + logout + role routing | E2: F-021,F-022 | F2: tools/gates/ord_01.sh | G2: bash tools/gates/ord_01.sh | H2: docs/evidence/ORD-01/20260110-162713 | I2: Exit 0 ONLY if all checks pass + artifacts exist; else NO-GO with blocker file | K2: P0 | L2: 24 | M2: NO-GO | N2: Copilot | O2: 2026-01-10 19:09:47 | P2: Copilot | R2: STRONG | S2: TRUE | T2: TRUE | U2: TEST_CASES
A3: ORD-02 | B3: Customer Core Navigation + Home Feed | C3: Qatar Home/Offers Feed | D3: Home feed, categories, offer list, offer detail navigation | F3: tools/gates/ord_02.sh | G3: bash tools/gates/ord_02.sh | H3: docs/evidence/ORD-02/20260110-182517 | I3: Exit 0 ONLY if all checks pass + artifacts exist; else NO-GO with blocker file | J3: ORD-01 | K3: P1 | L3: 16 | M3: NO-GO | N3: Copilot | O3: 2026-01-10 19:09:47 | P3: Copilot | Q3: No matching Feature_ID found in matrix by keyword; needs manual mapping from PDF evidence. | R3: STRONG | S3: TRUE | T3: TRUE | U3: TEST_CASES
A4: ORD-03 | B4: Offer Details + Save/Share | C4: Qatar Offer Details | D4: Offer details, save, history, basic tracking | E4: F-005,F-019 | F4: tools/gates/ord_03.sh | G4: bash tools/gates/ord_03.sh | H4: docs/evidence/ORD-03/20260110-182540 | I4: Exit 0 ONLY if all checks pass + artifacts exist; else NO-GO with blocker file | J4: ORD-02 | K4: P1 | L4: 16 | M4: NO-GO | N4: Copilot | O4: 2026-01-10 19:09:47 | P4: Copilot | R4: STRONG | S4: TRUE | T4: TRUE | U4: TEST_CASES
A5: ORD-04 | B5: Redeem QR end-to-end (Customer) | C5: Qatar Redeem Flow | D5: Generate redeem token/QR, redeem rules, success/failure states | E5: F-002,F-006,F-011,F-014 | F5: tools/gates/ord_04.sh | G5: bash tools/gates/ord_04.sh | H5: docs/evidence/ORD-04/20260110-182618 | I5: Exit 0 ONLY if all checks pass + artifacts exist; else NO-GO with blocker file | J5: ORD-01,ORD-03 | K5: P0 | L5: 24 | M5: NO-GO | N5: Copilot | O5: 2026-01-10 19:09:47 | P5: Copilot | R5: STRONG | S5: TRUE | T5: TRUE | U5: TEST_CASES
A6: ORD-05 | B6: Wallet / Points / Transactions | C6: Qatar Wallet | D6: Wallet balance, points accrual/spend, transaction history | E6: F-004,F-005,F-012,F-020 | F6: tools/gates/ord_05.sh | G6: bash tools/gates/ord_05.sh | H6: docs/evidence/ORD-05/20260110-182659 | I6: Exit 0 ONLY if all checks pass + artifacts exist; else NO-GO with blocker file | J6: ORD-04 | K6: P1 | L6: 16 | M6: NO-GO | N6: Copilot | O6: 2026-01-10 19:09:47 | P6: Copilot | R6: STRONG | S6: TRUE | T6: TRUE | U6: TEST_CASES
A7: ORD-06 | B7: Merchant Scan + Validate Redeem | C7: Qatar Merchant Redeem | D7: Merchant scans QR, validates, confirms redeem, writes DB proof | E7: F-015,F-017,F-024,F-025,F-026 | F7: tools/gates/ord_06.sh | G7: bash tools/gates/ord_06.sh | H7: docs/evidence/ORD-06/20260110-182654 | I7: Exit 0 ONLY if all checks pass + artifacts exist; else NO-GO with blocker file | J7: ORD-01,ORD-04 | K7: P0 | L7: 24 | M7: NO-GO | N7: Copilot | O7: 2026-01-10 19:09:47 | P7: Copilot | R7: STRONG | S7: TRUE | T7: TRUE | U7: TEST_CASES
A8: ORD-07 | B8: Merchant Offer Management (Minimal) | C8: Qatar Merchant Panel | D8: Merchant view offers, basic compliance flags, profile | E8: F-001,F-004,F-006,F-013,F-015,F-016,F-017,F-024,F-025,F-026,F-029,F-030,F-031,F-032,F-036 | F8: tools/gates/ord_07.sh | G8: bash tools/gates/ord_07.sh | H8: docs/evidence/ORD-07/20260110-182529 | I8: Exit 0 ONLY if all checks pass + artifacts exist; else NO-GO with blocker file | J8: ORD-01 | K8: P2 | L8: 10 | M8: NO-GO | N8: Copilot | O8: 2026-01-10 19:09:47 | P8: Copilot | R8: STRONG | S8: TRUE | T8: TRUE | U8: TEST_CASES
A9: ORD-08 | B9: Web Admin Moderation Console (Scope-defined) | C9: Qatar Admin Moderation | D9: Moderate merchants/offers/users; guard; audit trail | E9: F-001,F-004,F-006,F-013,F-014,F-015,F-016,F-017,F-018,F-019,F-020,F-024,F-025,F-026,F-031,F-036 | F9: tools/gates/ord_08.sh | G9: bash tools/gates/ord_08.sh | H9: docs/evidence/ORD-08/20260110-182523 | I9: Exit 0 ONLY if all checks pass + artifacts exist; else NO-GO with blocker file | J9: ORD-01 | K9: P1 | L9: 16 | M9: NO-GO | N9: Copilot | O9: 2026-01-10 19:09:47 | P9: Copilot | R9: STRONG | S9: TRUE | T9: TRUE | U9: TEST_CASES
A10: ORD-09 | B10: Notifications (Push/In-app) | C10: Qatar Notifications | D10: Push notifications + in-app inbox triggers for key events | E10: F-012,F-013,F-014,F-016 | F10: tools/gates/ord_09.sh | G10: bash tools/gates/ord_09.sh | H10: docs/evidence/ORD-09/20260110-182607 | I10: Exit 0 ONLY if all checks pass + artifacts exist; else NO-GO with blocker file | J10: ORD-01,ORD-02 | K10: P2 | L10: 10 | M10: NO-GO | N10: Copilot | O10: 2026-01-10 19:09:47 | P10: Copilot | R10: STRONG | S10: TRUE | T10: TRUE | U10: TEST_CASES
A11: ORD-10 | B11: Subscriptions + Entitlements | C11: Qatar Subscription/Paywall | D11: Subscription state machine, entitlement gating, renew/expire | E11: F-006,F-007,F-009,F-016 | F11: tools/gates/ord_10.sh | G11: bash tools/gates/ord_10.sh | H11: docs/evidence/ORD-10/20260110-182710 | I11: Exit 0 ONLY if all checks pass + artifacts exist; else NO-GO with blocker file | J11: ORD-01,ORD-05 | K11: P1 | L11: 16 | M11: NO-GO | N11: Copilot | O11: 2026-01-10 19:09:47 | P11: Copilot | R11: STRONG | S11: TRUE | T11: TRUE | U11: TEST_CASES
A12: ORD-11 | B12: Payments (Stripe test mode) + Webhooks | C12: Qatar Payments | D12: Checkout/payment creation, webhooks, idempotency, DB writes | E12: F-007,F-008,F-009 | F12: tools/gates/ord_11.sh | G12: bash tools/gates/ord_11.sh | H12: docs/evidence/ORD-11/20260110-182727 | I12: Exit 0 ONLY if all checks pass + artifacts exist; else NO-GO with blocker file | J12: ORD-10 | K12: P0 | L12: 24 | M12: NO-GO | N12: Copilot | O12: 2026-01-10 19:09:47 | P12: Copilot | R12: STRONG | S12: TRUE | T12: TRUE | U12: TEST_CASES
A13: ORD-12 | B13: Automation + Schedulers + Prod Activation | C13: Qatar Automation | D13: Schedulers run in prod, cloud scheduler config, cleanup jobs | E13: F-009,F-010,F-011,F-012,F-015,F-016,F-038 | F13: tools/gates/ord_12.sh | G13: bash tools/gates/ord_12.sh | H13: docs/evidence/ORD-12/20260110-182716 | I13: Exit 0 ONLY if all checks pass + artifacts exist; else NO-GO with blocker file | J13: ORD-04,ORD-06 | K13: P2 | L13: 10 | M13: NO-GO | N13: Copilot | O13: 2026-01-10 19:09:47 | P13: Copilot | R13: STRONG | S13: TRUE | T13: TRUE | U13: TEST_CASES
A14: ORD-13 | B14: DevOps Gate Auto (CI/CD + Evidence) | C14: Qatar Production Readiness | D14: One-button gate_auto to run all gates + produce artifacts | E14: F-006,F-007,F-022,F-027,F-028,F-033,F-038,F-041,F-044 | F14: tools/gates/ord_13.sh | G14: bash tools/gates/ord_13.sh | H14: docs/evidence/ORD-13/20260110-182738 | I14: Exit 0 ONLY if all checks pass + artifacts exist; else NO-GO with blocker file | J14: ORD-01,ORD-02,ORD-03,ORD-04,ORD-05,ORD-06,ORD-08,ORD-10,ORD-11,ORD-12 | K14: P0 | L14: 24 | M14: NO-GO | N14: Copilot | O14: 2026-01-10 19:09:47 | P14: Copilot | R14: STRONG | S14: TRUE | T14: TRUE | U14: TEST_CASES

Sheet PROJECT_DEFINITION
A1: Domain | B1: Description | C1: Actors | D1: Entry_Points | E1: Exit_Outcomes | F1: Notes
A2: Platform | B2: Location-based loyalty & offers platform connecting customers, merchants, and admins in Lebanon. | C2: Customer; Merchant; Admin | D2: Mobile apps (Customer/Merchant); Web Admin | E2: Offer discovery → QR redemption; points ledger; moderated offers; subscription gating | F2: Source: SECTION 1 project definition.
A3: Customer Flow | B3: Browse offers by location; generate QR for redemption; earn & track points; receive notifications. | C3: Customer | D3: Mobile Customer app: location permission, offers list, offer detail/QR | E3: Redeemed offer recorded; points updated; history visible | F3: Payments for subscription not active (SECTION 5/12).
A4: Merchant Flow | B4: Create offers; scan customer QR; enter PIN; complete redemption; basic analytics. | C4: Merchant | D4: Mobile Merchant app: create offer, QR scanner/PIN entry | E4: Offer created; redemption processed; points ledger updated | F4: Offer type selection missing; subscription UI gating missing.
A5: Admin Flow | B5: Moderate platform: approve/reject/disable offers; suspend/block merchants; ban/unban users; change roles. | C5: Admin | D5: Web Admin /admin/* routes (guarded by admin claim) | E5: Offers/merchants/users state updated via mutations | F5: Mobile Admin app is skeleton/removed; web admin is functional (SECTION 7).
A6: Subscriptions | B6: Customer ($8/mo) & Merchant ($20/mo) subscriptions intended; enforced at backend gates. | C6: Customer; Merchant | D6: Backend checks at QR gen / offer create / redemption | E6: Access granted/denied based on subscription status | F6: Real payments disabled; auto-renewal TODO (SECTION 5/12).
A7: Points | B7: Points balance + ledger; redemption history UI. | C7: Customer; Merchant | D7: Backend points functions; customer points screens | E7: Balance updated; ledger entries stored; history visible | F7: Confirmed wired (Points Tracking section).
A8: Automation | B8: Schedulers for compliance, cleanup, reminders; plus triggers for offer status notifications. | C8: Admin; System | D8: Cloud Scheduler / pubsub.schedule; Firestore triggers | E8: Tokens cleaned; reminders sent; compliance enforced | F8: Schedulers currently disabled via Cloud Scheduler API (SECTION 12).
A9: External Dependencies | B9: Stripe (payments), SMS gateway (OTP), Firebase Cloud Scheduler, FCM notifications, App stores. | C9: System | D9: Backend config/secrets; mobile app integrations | E9: Revenue processing; OTP auth; automated jobs; push notifications | F9: Multiple dependencies not enabled/configured (SECTION 5/6/12).

Sheet FULL_STACK_FEATURE_MATRIX
A1: Feature_ID | B1: Feature_Name | C1: Feature_Category | D1: Backend_Component | E1: Backend_Status | F1: Backend_Completion_% | G1: Mobile_Customer_Frontend | H1: Mobile_Customer_Status | I1: Mobile_Customer_Completion_% | J1: Mobile_Merchant_Frontend | K1: Mobile_Merchant_Status | L1: Mobile_Merchant_Completion_% | M1: Web_Admin_Frontend | N1: Web_Admin_Status | O1: Web_Admin_Completion_% | P1: API_or_Function_Name | Q1: Data_Model_Affected | R1: Dependencies | S1: Is_End_to_End_Working | T1: Blocker_Type | U1: Blocker_Description | V1: Priority | W1: Estimated_Effort_Hours | X1: Execution_Order | Y1: Notes | Z1: Last_Updated_At | AA1: Last_Updated_By | AB1: Evidence_Ref | AC1: Required_Order_IDs | AD1: Required_Test_IDs | AE1: Gate_Status
A2: F-001 | B2: Offer discovery by location (Haversine + fallback) | C2: Core Offers | D2: firebase-functions/src/core/offers.ts | E2: Done | F2: 100 | G2: mobile-customer offers list + location_service | H2: Done | I2: 100 | P2: getOffersByLocationFunc / coreGetOffersByLocation | Q2: offers, merchants | R2: Maps API optional | S2: YES | T2: None | V2: P2 | W2: 8 | X2: 21 | Y2: Verified MATCHED. | Z2: 2026-01-10 18:25:30 EET | AA2: Copilot | AB2: docs/evidence/ORD-07/20260110-182529 | AC2: ORD-07,ORD-08 | AE2: UNKNOWN
A3: F-002 | B3: Secure QR token generation (60s expiry, device binding) | C3: Redemption | D3: firebase-functions/src/core/qr.ts | E3: Done | F3: 100 | G3: mobile-customer offer_detail_screen QR display | H3: Done | I3: 100 | J3: mobile-merchant qr_scanner_screen scanner | K3: Done | L3: 100 | P3: generateSecureQRToken / coreGenerateSecureQRToken | Q3: qr_tokens, offers, users | R3: Firebase Functions | S3: YES | T3: None | V3: P2 | W3: 8 | X3: 22 | Y3: Verified MATCHED. | Z3: 2026-01-10 18:26:20 EET | AA3: Copilot | AB3: docs/evidence/ORD-04/20260110-182618 | AC3: ORD-04 | AE3: UNKNOWN
A4: F-003 | B4: One-time PIN per redemption (6-digit, crypto.randomInt) | C4: Redemption | D4: firebase-functions/src/core/qr.ts | E4: Done | F4: 100 | G4: Customer displays PIN (within QR flow) | H4: Done | I4: 100 | J4: Merchant PIN entry screen | K4: Done | L4: 100 | P4: coreValidatePIN / coreGeneratePIN | Q4: qr_tokens, redemptions | R4: Firebase Functions | S4: YES | T4: None | V4: P2 | W4: 8 | X4: 23 | Y4: Verified MATCHED. | Z4: 46030.158 | AA4: ChatGPT | AB4: PDF p2-3 'QR Generation & Redemption' (PIN generation/entry/validation) + SECTION 4 item 3 | AE4: UNKNOWN
A5: F-004 | B5: Offer redemption atomic transaction + idempotency | C5: Redemption | D5: firebase-functions/src/core/points.ts | E5: Done | F5: 100 | G5: Redeem button -> QR flow | H5: Done | I5: 100 | J5: Scan -> validate -> confirm redemption | K5: Done | L5: 100 | P5: processRedemption / coreValidateRedemption | Q5: redemptions, points_ledger, users | R5: Firestore transactions | S5: YES | T5: None | V5: P2 | W5: 12 | X5: 24 | Y5: Critical core flow. | Z5: 2026-01-10 18:27:01 EET | AA5: Copilot | AB5: docs/evidence/ORD-05/20260110-182659 | AC5: ORD-05,ORD-07,ORD-08 | AE5: UNKNOWN
A6: F-005 | B6: Points balance + ledger (history UI) | C6: Points | D6: firebase-functions/src/core/points.ts | E6: Done | F6: 100 | G6: points_history_screen(_v2) | H6: Done | I6: 100 | P6: getPointsBalance / ledger writes | Q6: points_ledger, users | R6: Firestore | S6: YES | T6: None | V6: P2 | W6: 8 | X6: 25 | Y6: Verified MATCHED. | Z6: 2026-01-10 18:27:01 EET | AA6: Copilot | AB6: docs/evidence/ORD-05/20260110-182659 | AC6: ORD-03,ORD-05 | AE6: UNKNOWN
A7: F-006 | B7: Subscription enforcement at gates (QR gen / offer create / redemption) | C7: Subscriptions | D7: firebase-functions/src/core/qr.ts + core/offers.ts + core/indexCore.ts | E7: Done | F7: 100 | G7: Subscription status UI model only (no gating UX) | H7: Partial | I7: 20 | J7: checkSubscriptionAccess() exists but not gating offer creation UI | K7: Partial | L7: 20 | M7: Admin can view/suspend indirectly via claims/Firestore | N7: Partial | O7: 40 | P7: subscription checks inside core functions | Q7: users, subscriptions, claims | R7: Stripe (planned) | S7: YES | T7: Tech | U7: Backend enforces subscription checks, but customer/merchant UIs do not gate or show clear expiry errors. | V7: P1 | W7: 24 | X7: 26 | Y7: Backend enforces, but customer/merchant UX not complete. | Z7: 2026-01-10 18:27:40 EET | AA7: Copilot | AB7: docs/evidence/ORD-13/20260110-182738 | AC7: ORD-04,ORD-07,ORD-08,ORD-10,ORD-13 | AE7: UNKNOWN
A8: F-007 | B8: Subscription payments (Stripe) enabled + deployed | C8: Payments | D8: firebase-functions/src/stripe.ts | E8: Partial | F8: 30 | G8: No payment UI | H8: Not Started | I8: 0 | J8: No payment UI | K8: Not Started | L8: 0 | M8: No pricing controls; Stripe disabled | N8: Not Started | O8: 0 | P8: initiatePaymentCallable / stripeWebhook | Q8: subscriptions, payments | R8: Stripe | S8: YES | T8: Business | U8: Stripe disabled (STRIPE_ENABLED=0); no mobile payment UI; no payment method storage. | V8: P0 | W8: 80 | X8: 3 | Y8: Hard blocker #1 and #6 combined. | Z8: 2026-01-10 18:27:40 EET | AA8: Copilot | AB8: docs/evidence/ORD-13/20260110-182738 | AC8: ORD-10,ORD-11,ORD-13 | AD8: TC-0003,TC-0004,TC-0005 | AE8: UNKNOWN
A9: F-008 | B9: Payment webhook handlers working in production | C9: Payments | D9: firebase-functions/src/paymentWebhooks.ts | E9: Partial | F9: 20 | P9: omtWebhook/whishWebhook/cardWebhook | Q9: payments, subscriptions | R9: IAM perms; gateways | S9: YES | T9: Tech | U9: Webhook handlers exist but commented/unfinished; required IAM/permissions not granted. | V9: P0 | W9: 80 | X9: 4 | Y9: Hard blocker #6. | Z9: 2026-01-10 18:27:29 EET | AA9: Copilot | AB9: docs/evidence/ORD-11/20260110-182727 | AC9: ORD-11 | AD9: TC-0006 | AE9: UNKNOWN
A10: F-009 | B10: Subscription auto-renewal (real charge, not simulated) | C10: Payments/Automation | D10: firebase-functions/src/subscriptionAutomation.ts | E10: Partial | F10: 30 | M10: Admin can view users, not renewals UI | N10: Not Started | O10: 0 | P10: processSubscriptionRenewals (pubsub) | Q10: subscriptions, payments | R10: Stripe; Scheduler | S10: YES | T10: Tech | U10: Auto-renewal scheduled but disabled; TODO payment processing; simulated success. | V10: P0 | W10: 24 | X10: 5 | Y10: Hard blocker #3. | Z10: 2026-01-10 18:27:29 EET | AA10: Copilot | AB10: docs/evidence/ORD-11/20260110-182727 | AC10: ORD-10,ORD-11,ORD-12 | AD10: TC-0007 | AE10: UNKNOWN
A11: F-010 | B11: Cloud Scheduler enabled + scheduled jobs executing | C11: Automation/Infra | D11: firebase-functions/src/index.ts + Scheduler config | E11: Not Started | F11: 0 | P11: pubsub.schedule jobs | Q11: N/A | R11: Google Cloud Scheduler | S11: YES | T11: Infra | U11: Cloud Scheduler API not enabled; scheduled jobs not executing in production. | V11: P0 | W11: 16 | X11: 2 | Y11: Hard blocker #4. | Z11: 2026-01-10 18:27:18 EET | AA11: Copilot | AB11: docs/evidence/ORD-12/20260110-182716 | AC11: ORD-12 | AD11: TC-0002 | AE11: UNKNOWN
A12: F-011 | B12: QR token cleanup scheduler (7-day retention) | C12: Automation | D12: firebase-functions/src/phase3Scheduler.ts | E12: Partial | F12: 60 | P12: cleanupExpiredQRTokens | Q12: qr_tokens | R12: Scheduler | S12: YES | T12: Infra | U12: Scheduler code exists, but Cloud Scheduler disabled → not proven executing end-to-end. | V12: P1 | W12: 8 | X12: 9 | Y12: Confirmed working. | Z12: 2026-01-10 18:27:18 EET | AA12: Copilot | AB12: docs/evidence/ORD-12/20260110-182716 | AC12: ORD-04,ORD-12 | AD12: TC-0012 | AE12: UNKNOWN
A13: F-012 | B13: Points expiry warnings notifications | C13: Automation/Notifications | D13: firebase-functions/src/phase3Scheduler.ts | E13: Partial | F13: 60 | G13: Receives notifications via FCM | H13: Done | I13: 100 | J13: Receives notifications via FCM | K13: Done | L13: 100 | P13: sendPointsExpiryWarnings | Q13: users, points_ledger | R13: Firebase FCM | S13: YES | T13: Infra | U13: Scheduler code exists, but Cloud Scheduler disabled → not proven executing end-to-end. | V13: P1 | W13: 8 | X13: 10 | Y13: Working. | Z13: 2026-01-10 18:27:18 EET | AA13: Copilot | AB13: docs/evidence/ORD-12/20260110-182716 | AC13: ORD-05,ORD-09,ORD-12 | AE13: UNKNOWN
A14: F-013 | B14: Offer status change notifications (trigger on admin action) | C14: Notifications | D14: firebase-functions/src/phase3Scheduler.ts | E14: Done | F14: 100 | G14: FCM receive handler | H14: Done | I14: 100 | J14: FCM receive handler | K14: Done | L14: 100 | M14: Admin triggers status updates | N14: Done | O14: 100 | P14: notifyOfferStatusChange | Q14: offers, users | R14: Firebase FCM | S14: YES | T14: None | V14: P2 | W14: 6 | X14: 27 | Y14: Working. | Z14: 2026-01-10 18:26:09 EET | AA14: Copilot | AB14: docs/evidence/ORD-09/20260110-182607 | AC14: ORD-07,ORD-08,ORD-09 | AE14: UNKNOWN
A15: F-014 | B15: Admin batch notifications (500-token batching) | C15: Notifications/Admin | D15: firebase-functions/src/phase3Notifications.ts | E15: Done | F15: 100 | M15: Web admin UI not present (function callable only) | N15: Partial | O15: 30 | P15: sendBatchNotification (admin-only) | Q15: fcm_tokens | R15: Firebase FCM | S15: YES | T15: Tech | U15: Backend callable exists; PDF indicates no admin UI for push campaigns. | V15: P2 | W15: 24 | X15: 28 | Y15: Report: no campaign UI. | Z15: 2026-01-10 18:26:20 EET | AA15: Copilot | AB15: docs/evidence/ORD-04/20260110-182618 | AC15: ORD-04,ORD-08,ORD-09 | AE15: UNKNOWN
A16: F-015 | B16: Merchant compliance (5-offer threshold) enforced in UX/catalog | C16: Merchant Ops/Automation | D16: firebase-functions/src/phase3Scheduler.ts | E16: Partial | F16: 60 | J16: No merchant-facing warning / gating | K16: Not Started | L16: 0 | P16: enforceMerchantCompliance | Q16: merchants, offers | R16: Scheduler | S16: YES | T16: Infra | U16: Scheduler code exists, but Cloud Scheduler disabled → not proven executing end-to-end. | V16: P1 | W16: 24 | X16: 11 | Y16: Partial per report. | Z16: 2026-01-10 18:27:18 EET | AA16: Copilot | AB16: docs/evidence/ORD-12/20260110-182716 | AC16: ORD-06,ORD-07,ORD-08,ORD-12 | AD16: TC-0013 | AE16: UNKNOWN
A17: F-016 | B17: Offer/subscription expiry reminders sent automatically | C17: Automation/Notifications | D17: firebase-functions/src/subscriptionAutomation.ts | E17: Partial | F17: 60 | G17: Receives notifications (FCM ready) | H17: Done | I17: 100 | J17: Receives notifications (FCM ready) | K17: Done | L17: 100 | P17: sendExpiryReminders | Q17: subscriptions | R17: Cloud Scheduler + FCM | S17: YES | T17: Infra | U17: Scheduler code exists, but Cloud Scheduler disabled → not proven executing end-to-end. | V17: P1 | W17: 16 | X17: 12 | Y17: Partial per report. | Z17: 2026-01-10 18:27:18 EET | AA17: Copilot | AB17: docs/evidence/ORD-12/20260110-182716 | AC17: ORD-07,ORD-08,ORD-09,ORD-10,ORD-12 | AD17: TC-0014 | AE17: UNKNOWN
A18: F-017 | B18: Web Admin moderation console (offers/merchants/users mutations) | C18: Web Admin | D18: firebase-functions/src/index.ts + Firestore | E18: Done | F18: 100 | M18: web-admin pages/admin/* | N18: Done | O18: 100 | P18: approveOffer/rejectOffer/setCustomClaims + updateDoc mutations | Q18: offers, merchants, users | R18: Firebase Auth claims | S18: YES | T18: None | V18: P2 | W18: 16 | X18: 29 | Y18: Confirmed MATCHED. | Z18: 2026-01-10 18:26:56 EET | AA18: Copilot | AB18: docs/evidence/ORD-06/20260110-182654 | AC18: ORD-06,ORD-07,ORD-08 | AE18: UNKNOWN
A19: F-018 | B19: Admin route guard (role=admin claim enforcement) | C19: Security/Web Admin | D19: apps/web-admin/components/AdminGuard.tsx | E19: Done | F19: 100 | M19: AdminGuard.tsx | N19: Done | O19: 100 | P19: N/A | Q19: users, claims | R19: Firebase Auth | S19: YES | T19: None | V19: P2 | W19: 4 | X19: 30 | Y19: Working. | Z19: 2026-01-10 18:25:25 EET | AA19: Copilot | AB19: docs/evidence/ORD-08/20260110-182523 | AC19: ORD-08 | AE19: UNKNOWN
A20: F-019 | B20: Admin view redemptions history (screen + queries) | C20: Web Admin/Analytics | D20: N/A | E20: Not Started | F20: 0 | M20: pages/admin/* missing screen | N20: Not Started | O20: 0 | P20: N/A | Q20: redemptions | R20: Firestore | S20: YES | T20: Tech | U20: No evidence in PDF of working UI/queries or backend support for this feature. | V20: P2 | W20: 24 | X20: 31 | Y20: Not required for launch but useful. | Z20: 2026-01-10 18:25:42 EET | AA20: Copilot | AB20: docs/evidence/ORD-03/20260110-182540 | AC20: ORD-03,ORD-08 | AE20: UNKNOWN
A21: F-020 | B21: Admin adjust/refund points (UI + backend function) | C21: Web Admin/Points | D21: N/A | E21: Not Started | F21: 0 | M21: No UI / no backend function | N21: Not Started | O21: 0 | P21: N/A | Q21: points_ledger, users | R21: Firestore | S21: YES | T21: Tech | U21: No evidence in PDF of working UI/queries or backend support for this feature. | V21: P2 | W21: 32 | X21: 32 | Y21: Post-launch feature. | Z21: 2026-01-10 18:27:01 EET | AA21: Copilot | AB21: docs/evidence/ORD-05/20260110-182659 | AC21: ORD-05,ORD-08 | AE21: UNKNOWN
A22: F-021 | B22: Phone/OTP authentication end-to-end | C22: Auth | D22: firebase-functions/src/sms.ts | E22: Partial | F22: 20 | G22: Apps use email/password + Google only | H22: Not Started | I22: 0 | J22: Apps use email/password + Google only | K22: Not Started | L22: 0 | P22: sendSMS / verifyOTP | Q22: users, otp | R22: Lebanese SMS gateway | S22: YES | T22: Tech | U22: SMS functions exist but not wired; apps use email/Google only. | V22: P0 | W22: 24 | X22: 8 | Y22: Hard blocker #5 + missing gateway. | Z22: 2026-01-10 16:27:15 EET | AA22: Copilot | AB22: docs/evidence/ORD-01/20260110-162713 | AC22: ORD-01 | AD22: TC-0008 | AE22: UNKNOWN
A23: F-022 | B23: Lebanese SMS gateway integration (Alfa/Touch/Ogero) | C23: Infra/Auth | D23: N/A | E23: Not Started | F23: 0 | P23: N/A | Q23: sms_logs | R23: SMS provider | S23: YES | T23: Infra | U23: No Lebanese gateway integration (Ogero/Alfa/Touch); only generic SMS skeleton. | V23: P2 | W23: 80 | X23: 33 | Y23: Listed as missing. | Z23: 2026-01-10 18:27:40 EET | AA23: Copilot | AB23: docs/evidence/ORD-13/20260110-182738 | AC23: ORD-01,ORD-13 | AD23: TC-0009 | AE23: UNKNOWN
A24: F-023 | B24: Arabic + English i18n across apps and web | C24: Localization | D24: N/A | E24: Not Started | F24: 0 | G24: No localization package/framework | H24: Not Started | I24: 0 | J24: No localization package/framework | K24: Not Started | L24: 0 | M24: English-only | N24: Not Started | O24: 0 | P24: N/A | Q24: ui_strings | R24: i18n libs | S24: NO | T24: Business | U24: No localization/i18n framework detected; English-only. | V24: P1 | W24: 80 | X24: 13 | Y24: High-impact before Lebanon launch. | Z24: 46030.158 | AA24: ChatGPT | AB24: PDF SECTION 5 item 7 + High-impact blockers | AD24: TC-0015 | AE24: UNKNOWN
A25: F-024 | B25: Merchant offer type selection UI (B1G1/Percent/Fixed) | C25: Merchant UX | D25: Backend supports offer types | E25: Done | F25: 100 | J25: Create offer screen missing dropdown | K25: Not Started | L25: 0 | P25: createOffer | Q25: offers | R25: N/A | S25: YES | T25: Tech | U25: Backend supports offer types, but merchant UI lacks selection dropdown. | V25: P2 | W25: 16 | X25: 34 | Y25: Partial per report. | Z25: 2026-01-10 18:26:56 EET | AA25: Copilot | AB25: docs/evidence/ORD-06/20260110-182654 | AC25: ORD-06,ORD-07,ORD-08 | AE25: UNKNOWN
A26: F-025 | B26: Merchant analytics dashboard (trends, deeper metrics) | C26: Merchant Analytics | D26: N/A | E26: Partial | F26: 30 | J26: Basic metrics only | K26: Partial | L26: 30 | P26: N/A | Q26: offers, redemptions | R26: Firestore | S26: YES | T26: Business | U26: Only basic metrics; no trends/cohorts. | V26: P2 | W26: 40 | X26: 35 | Y26: Not hard blocker. | Z26: 2026-01-10 18:26:56 EET | AA26: Copilot | AB26: docs/evidence/ORD-06/20260110-182654 | AC26: ORD-06,ORD-07,ORD-08 | AE26: UNKNOWN
A27: F-026 | B27: Merchant manage multiple branches (UI + switching) | C27: Merchant UX | D27: Schema supports branches | E27: Partial | F27: 50 | J27: No UI for branch switching | K27: Partial | L27: 10 | P27: N/A | Q27: merchants, branches | R27: Firestore | S27: YES | T27: Business | U27: Schema supports branches but no UI for switching/management. | V27: P2 | W27: 24 | X27: 36 | Y27: Optional. | Z27: 2026-01-10 18:26:56 EET | AA27: Copilot | AB27: docs/evidence/ORD-06/20260110-182654 | AC27: ORD-06,ORD-07,ORD-08 | AE27: UNKNOWN
A28: F-027 | B28: iOS build signing + provisioning for App Store | C28: Deployment | D28: N/A | E28: Not Started | F28: 0 | G28: iOS signing missing | H28: Not Started | I28: 0 | J28: iOS signing missing | K28: Not Started | L28: 0 | P28: N/A | Q28: N/A | R28: Apple Developer | S28: YES | T28: Infra | U28: iOS signing missing; no Xcode config in ios/ folder. | V28: P0 | W28: 40 | X28: 6 | Y28: Hard blocker #7. | Z28: 2026-01-10 18:27:40 EET | AA28: Copilot | AB28: docs/evidence/ORD-13/20260110-182738 | AC28: ORD-13 | AD28: TC-0010 | AE28: UNKNOWN
A29: F-028 | B29: Android signing (keystore configured) | C29: Deployment | D29: android/app/build.gradle | E29: Partial | F29: 40 | G29: Android signing partial | H29: Partial | I29: 30 | J29: Android signing partial | K29: Partial | L29: 30 | P29: N/A | Q29: N/A | R29: Android Keystore | S29: YES | T29: Infra | U29: Android signing partial; keystore not configured. | V29: P0 | W29: 40 | X29: 7 | Y29: Hard blocker #7. | Z29: 2026-01-10 18:27:40 EET | AA29: Copilot | AB29: docs/evidence/ORD-13/20260110-182738 | AC29: ORD-13 | AD29: TC-0011 | AE29: UNKNOWN
A30: F-029 | B30: Privacy policy hosted + linked in apps | C30: Compliance/Legal | D30: N/A | E30: Not Started | F30: 0 | G30: Not linked | H30: Not Started | I30: 0 | J30: Not linked | K30: Not Started | L30: 0 | M30: Not linked | N30: Not Started | O30: 0 | P30: N/A | Q30: N/A | R30: Hosting | S30: YES | T30: Business | U30: Privacy policy not hosted/linked. | V30: P2 | W30: 16 | X30: 37 | Y30: Required for stores. | Z30: 2026-01-10 18:25:30 EET | AA30: Copilot | AB30: docs/evidence/ORD-07/20260110-182529 | AC30: ORD-07 | AE30: UNKNOWN
A31: F-030 | B31: Terms of service hosted + linked in apps | C31: Compliance/Legal | D31: N/A | E31: Not Started | F31: 0 | G31: Not linked | H31: Not Started | I31: 0 | J31: Not linked | K31: Not Started | L31: 0 | M31: Not linked | N31: Not Started | O31: 0 | P31: N/A | Q31: N/A | R31: Hosting | S31: YES | T31: Business | U31: Terms of service not hosted/linked. | V31: P2 | W31: 16 | X31: 38 | Y31: Required for stores. | Z31: 2026-01-10 18:25:30 EET | AA31: Copilot | AB31: docs/evidence/ORD-07/20260110-182529 | AC31: ORD-07 | AE31: UNKNOWN
A32: F-031 | B32: GDPR data export (user request) wired to UI | C32: Compliance | D32: firebase-functions/src/privacy.ts (disabled) | E32: Partial | F32: 20 | G32: No UI entry | H32: Not Started | I32: 0 | J32: No UI entry | K32: Not Started | L32: 0 | P32: exportUserData (disabled) | Q32: users, exports | R32: Permissions | S32: YES | T32: Tech | U32: Export function exists but disabled; no UI entry points. | V32: P1 | W32: 24 | X32: 14 | Y32: High-impact before launch. | Z32: 2026-01-10 18:25:30 EET | AA32: Copilot | AB32: docs/evidence/ORD-07/20260110-182529 | AC32: ORD-07,ORD-08 | AD32: TC-0016 | AE32: UNKNOWN
A33: F-032 | B33: GDPR data deletion wired to UI | C33: Compliance | D33: firebase-functions/src/privacy.ts (disabled) | E33: Partial | F33: 20 | G33: No UI entry | H33: Not Started | I33: 0 | J33: No UI entry | K33: Not Started | L33: 0 | P33: deleteUserData (disabled) | Q33: users | R33: Permissions | S33: YES | T33: Tech | U33: Deletion function exists but disabled; no UI entry points. | V33: P1 | W33: 24 | X33: 15 | Y33: High-impact before launch. | Z33: 2026-01-10 18:25:30 EET | AA33: Copilot | AB33: docs/evidence/ORD-07/20260110-182529 | AC33: ORD-07 | AD33: TC-0017 | AE33: UNKNOWN
A34: F-033 | B34: Production monitoring + alerting (Sentry/Datadog) configured | C34: Observability | D34: firebase-functions/src/monitoring.ts (checks only) | E34: Partial | F34: 10 | G34: No crash reporting config | H34: Partial | I34: 10 | J34: No crash reporting config | K34: Partial | L34: 10 | P34: N/A | Q34: logs | R34: Sentry/other | S34: YES | T34: Infra | U34: Crash reporting checks exist but not configured; no alerting/monitoring. | V34: P1 | W34: 40 | X34: 16 | Y34: High-impact before launch. | Z34: 2026-01-10 18:27:40 EET | AA34: Copilot | AB34: docs/evidence/ORD-13/20260110-182738 | AC34: ORD-13 | AD34: TC-0018 | AE34: UNKNOWN
A35: F-034 | B35: Rate limiting enforced in production (rules / middleware) | C35: Security | D35: Exists but not deployed in Firebase rules | E35: Not Started | F35: 0 | P35: N/A | Q35: N/A | R35: Firebase rules | S35: NO | T35: Infra | U35: No rate limiting deployed. | V35: P1 | W35: 8 | X35: 17 | Y35: Listed as missing. | Z35: 46030.158 | AA35: ChatGPT | AB35: PDF SECTION 6 item 5 + High-impact blocker | AD35: TC-0019 | AE35: UNKNOWN
A36: F-035 | B36: Backend input validation enforced on all functions | C36: Security/Data Integrity | D36: Schemas exist but not enforced on 11/15 functions | E36: Partial | F36: 40 | P36: various httpsCallable | Q36: various | R36: Zod/validators | S36: NO | T36: Tech | U36: Schemas exist but not enforced across functions (11/15 not enforced per PDF). | V36: P1 | W36: 24 | X36: 18 | Y36: High-impact. | Z36: 46030.158 | AA36: ChatGPT | AB36: PDF SECTION 6 item 6 + High-impact blocker | AD36: TC-0020 | AE36: UNKNOWN
A37: F-036 | B37: Audit logging system (write + admin view) | C37: Security/Compliance | D37: N/A | E37: Not Started | F37: 0 | M37: No UI | N37: Not Started | O37: 0 | P37: N/A | Q37: audit_logs | R37: Firestore | S37: YES | T37: Business | U37: No audit log collection or admin view. | V37: P1 | W37: 80 | X37: 19 | Y37: High-impact. | Z37: 2026-01-10 18:25:30 EET | AA37: Copilot | AB37: docs/evidence/ORD-07/20260110-182529 | AC37: ORD-07,ORD-08 | AD37: TC-0021 | AE37: UNKNOWN
A38: F-037 | B38: Automated database backups | C38: Infra | D38: Manual script exists, no scheduler | E38: Partial | F38: 20 | P38: N/A | Q38: firestore backups | R38: Scheduler | S38: NO | T38: Infra | U38: Manual script exists; no scheduler/automation. | V38: P1 | W38: 8 | X38: 20 | Y38: High-impact. | Z38: 46030.158 | AA38: ChatGPT | AB38: PDF SECTION 6 item 8 + High-impact blocker | AD38: TC-0022 | AE38: UNKNOWN
A39: F-038 | B39: CI/CD pipeline (build/test/deploy automation) | C39: DevOps | D39: N/A | E39: Not Started | F39: 0 | P39: N/A | Q39: N/A | R39: GitHub Actions/CI | S39: YES | T39: Infra | U39: No CI/CD pipeline. | V39: P2 | W39: 40 | X39: 39 | Y39: Missing. | Z39: 2026-01-10 18:27:40 EET | AA39: Copilot | AB39: docs/evidence/ORD-13/20260110-182738 | AC39: ORD-12,ORD-13 | AE39: UNKNOWN
A40: F-039 | B40: End-to-end tests for key flows | C40: QA | D40: Backend untested; no e2e suite | E40: Not Started | F40: 0 | G40: No e2e suite | H40: Not Started | I40: 0 | J40: No e2e suite | K40: Not Started | L40: 0 | P40: N/A | Q40: N/A | R40: Playwright/Flutter integration tests | S40: NO | T40: Tech | U40: No e2e test suite evidenced in PDF. | V40: P2 | W40: 40 | X40: 40 | Y40: Recommended 10 days in report. | Z40: 46030.158 | AA40: ChatGPT | AB40: PDF does not provide evidence of e2e test suite; listed as missing in SECTION 6 (general) | AE40: UNKNOWN
...

Sheet PROGRESS_CALCULATION
A1: Metric | B1: Value | D1: Feature_ID | E1: Priority | F1: Row_Progress_% | G1: Weight
A2: Overall Project Progress % | B2: =IFERROR(SUMPRODUCT(F2:F45,G2:G45)/SUM(G2:G45),0) | D2: =FULL_STACK_FEATURE_MATRIX!A2 | E2: =FULL_STACK_FEATURE_MATRIX!V2 | F2: =MIN(IF(FULL_STACK_FEATURE_MATRIX!F2="",0,FULL_STACK_FEATURE_MATRIX!F2),IF(FULL_STACK_FEATURE_MATRIX!G2="",100,FULL_STACK_FEATURE_MATRIX!I2),IF(FULL_STACK_FEATURE_MATRIX!J2="",100,FULL_STACK_FEATURE_MATRIX!L2),IF(FULL_STACK_FEATURE_MATRIX!M2="",100,FULL_STACK_FEATURE_MATRIX!O2)) | G2: =IF(E2="P0",3,IF(E2="P1",2,1))
A3: Mobile Customer — Frontend % | B3: =IFERROR(SUMPRODUCT(--(FULL_STACK_FEATURE_MATRIX!$G$2:$G$45<>""),FULL_STACK_FEATURE_MATRIX!$I$2:$I$45)/SUMPRODUCT(--(FULL_STACK_FEATURE_MATRIX!$G$2:$G$45<>"")),0) | D3: =FULL_STACK_FEATURE_MATRIX!A3 | E3: =FULL_STACK_FEATURE_MATRIX!V3 | F3: =MIN(IF(FULL_STACK_FEATURE_MATRIX!F3="",0,FULL_STACK_FEATURE_MATRIX!F3),IF(FULL_STACK_FEATURE_MATRIX!G3="",100,FULL_STACK_FEATURE_MATRIX!I3),IF(FULL_STACK_FEATURE_MATRIX!J3="",100,FULL_STACK_FEATURE_MATRIX!L3),IF(FULL_STACK_FEATURE_MATRIX!M3="",100,FULL_STACK_FEATURE_MATRIX!O3)) | G3: =IF(E3="P0",3,IF(E3="P1",2,1))
A4: Mobile Customer — Backend % | B4: =IFERROR(SUMPRODUCT(--(FULL_STACK_FEATURE_MATRIX!$G$2:$G$45<>""),FULL_STACK_FEATURE_MATRIX!$F$2:$F$45)/SUMPRODUCT(--(FULL_STACK_FEATURE_MATRIX!$G$2:$G$45<>"")),0) | D4: =FULL_STACK_FEATURE_MATRIX!A4 | E4: =FULL_STACK_FEATURE_MATRIX!V4 | F4: =MIN(IF(FULL_STACK_FEATURE_MATRIX!F4="",0,FULL_STACK_FEATURE_MATRIX!F4),IF(FULL_STACK_FEATURE_MATRIX!G4="",100,FULL_STACK_FEATURE_MATRIX!I4),IF(FULL_STACK_FEATURE_MATRIX!J4="",100,FULL_STACK_FEATURE_MATRIX!L4),IF(FULL_STACK_FEATURE_MATRIX!M4="",100,FULL_STACK_FEATURE_MATRIX!O4)) | G4: =IF(E4="P0",3,IF(E4="P1",2,1))
A5: Mobile Customer — Full-Stack % (MIN) | B5: =MIN(B3,B4) | D5: =FULL_STACK_FEATURE_MATRIX!A5 | E5: =FULL_STACK_FEATURE_MATRIX!V5 | F5: =MIN(IF(FULL_STACK_FEATURE_MATRIX!F5="",0,FULL_STACK_FEATURE_MATRIX!F5),IF(FULL_STACK_FEATURE_MATRIX!G5="",100,FULL_STACK_FEATURE_MATRIX!I5),IF(FULL_STACK_FEATURE_MATRIX!J5="",100,FULL_STACK_FEATURE_MATRIX!L5),IF(FULL_STACK_FEATURE_MATRIX!M5="",100,FULL_STACK_FEATURE_MATRIX!O5)) | G5: =IF(E5="P0",3,IF(E5="P1",2,1))
A6: Mobile Merchant — Frontend % | B6: =IFERROR(SUMPRODUCT(--(FULL_STACK_FEATURE_MATRIX!$J$2:$J$45<>""),FULL_STACK_FEATURE_MATRIX!$L$2:$L$45)/SUMPRODUCT(--(FULL_STACK_FEATURE_MATRIX!$J$2:$J$45<>"")),0) | D6: =FULL_STACK_FEATURE_MATRIX!A6 | E6: =FULL_STACK_FEATURE_MATRIX!V6 | F6: =MIN(IF(FULL_STACK_FEATURE_MATRIX!F6="",0,FULL_STACK_FEATURE_MATRIX!F6),IF(FULL_STACK_FEATURE_MATRIX!G6="",100,FULL_STACK_FEATURE_MATRIX!I6),IF(FULL_STACK_FEATURE_MATRIX!J6="",100,FULL_STACK_FEATURE_MATRIX!L6),IF(FULL_STACK_FEATURE_MATRIX!M6="",100,FULL_STACK_FEATURE_MATRIX!O6)) | G6: =IF(E6="P0",3,IF(E6="P1",2,1))
A7: Mobile Merchant — Backend % | B7: =IFERROR(SUMPRODUCT(--(FULL_STACK_FEATURE_MATRIX!$J$2:$J$45<>""),FULL_STACK_FEATURE_MATRIX!$F$2:$F$45)/SUMPRODUCT(--(FULL_STACK_FEATURE_MATRIX!$J$2:$J$45<>"")),0) | D7: =FULL_STACK_FEATURE_MATRIX!A7 | E7: =FULL_STACK_FEATURE_MATRIX!V7 | F7: =MIN(IF(FULL_STACK_FEATURE_MATRIX!F7="",0,FULL_STACK_FEATURE_MATRIX!F7),IF(FULL_STACK_FEATURE_MATRIX!G7="",100,FULL_STACK_FEATURE_MATRIX!I7),IF(FULL_STACK_FEATURE_MATRIX!J7="",100,FULL_STACK_FEATURE_MATRIX!L7),IF(FULL_STACK_FEATURE_MATRIX!M7="",100,FULL_STACK_FEATURE_MATRIX!O7)) | G7: =IF(E7="P0",3,IF(E7="P1",2,1))
A8: Mobile Merchant — Full-Stack % (MIN) | B8: =MIN(B6,B7) | D8: =FULL_STACK_FEATURE_MATRIX!A8 | E8: =FULL_STACK_FEATURE_MATRIX!V8 | F8: =MIN(IF(FULL_STACK_FEATURE_MATRIX!F8="",0,FULL_STACK_FEATURE_MATRIX!F8),IF(FULL_STACK_FEATURE_MATRIX!G8="",100,FULL_STACK_FEATURE_MATRIX!I8),IF(FULL_STACK_FEATURE_MATRIX!J8="",100,FULL_STACK_FEATURE_MATRIX!L8),IF(FULL_STACK_FEATURE_MATRIX!M8="",100,FULL_STACK_FEATURE_MATRIX!O8)) | G8: =IF(E8="P0",3,IF(E8="P1",2,1))
A9: Web Admin — Frontend % | B9: =IFERROR(SUMPRODUCT(--(FULL_STACK_FEATURE_MATRIX!$M$2:$M$45<>""),FULL_STACK_FEATURE_MATRIX!$O$2:$O$45)/SUMPRODUCT(--(FULL_STACK_FEATURE_MATRIX!$M$2:$M$45<>"")),0) | D9: =FULL_STACK_FEATURE_MATRIX!A9 | E9: =FULL_STACK_FEATURE_MATRIX!V9 | F9: =MIN(IF(FULL_STACK_FEATURE_MATRIX!F9="",0,FULL_STACK_FEATURE_MATRIX!F9),IF(FULL_STACK_FEATURE_MATRIX!G9="",100,FULL_STACK_FEATURE_MATRIX!I9),IF(FULL_STACK_FEATURE_MATRIX!J9="",100,FULL_STACK_FEATURE_MATRIX!L9),IF(FULL_STACK_FEATURE_MATRIX!M9="",100,FULL_STACK_FEATURE_MATRIX!O9)) | G9: =IF(E9="P0",3,IF(E9="P1",2,1))
A10: Web Admin — Backend % | B10: =IFERROR(SUMPRODUCT(--(FULL_STACK_FEATURE_MATRIX!$M$2:$M$45<>""),FULL_STACK_FEATURE_MATRIX!$F$2:$F$45)/SUMPRODUCT(--(FULL_STACK_FEATURE_MATRIX!$M$2:$M$45<>"")),0) | D10: =FULL_STACK_FEATURE_MATRIX!A10 | E10: =FULL_STACK_FEATURE_MATRIX!V10 | F10: =MIN(IF(FULL_STACK_FEATURE_MATRIX!F10="",0,FULL_STACK_FEATURE_MATRIX!F10),IF(FULL_STACK_FEATURE_MATRIX!G10="",100,FULL_STACK_FEATURE_MATRIX!I10),IF(FULL_STACK_FEATURE_MATRIX!J10="",100,FULL_STACK_FEATURE_MATRIX!L10),IF(FULL_STACK_FEATURE_MATRIX!M10="",100,FULL_STACK_FEATURE_MATRIX!O10)) | G10: =IF(E10="P0",3,IF(E10="P1",2,1))
A11: Web Admin — Full-Stack % (MIN) | B11: =MIN(B9,B10) | D11: =FULL_STACK_FEATURE_MATRIX!A11 | E11: =FULL_STACK_FEATURE_MATRIX!V11 | F11: =MIN(IF(FULL_STACK_FEATURE_MATRIX!F11="",0,FULL_STACK_FEATURE_MATRIX!F11),IF(FULL_STACK_FEATURE_MATRIX!G11="",100,FULL_STACK_FEATURE_MATRIX!I11),IF(FULL_STACK_FEATURE_MATRIX!J11="",100,FULL_STACK_FEATURE_MATRIX!L11),IF(FULL_STACK_FEATURE_MATRIX!M11="",100,FULL_STACK_FEATURE_MATRIX!O11)) | G11: =IF(E11="P0",3,IF(E11="P1",2,1))
D12: =FULL_STACK_FEATURE_MATRIX!A12 | E12: =FULL_STACK_FEATURE_MATRIX!V12 | F12: =MIN(IF(FULL_STACK_FEATURE_MATRIX!F12="",0,FULL_STACK_FEATURE_MATRIX!F12),IF(FULL_STACK_FEATURE_MATRIX!G12="",100,FULL_STACK_FEATURE_MATRIX!I12),IF(FULL_STACK_FEATURE_MATRIX!J12="",100,FULL_STACK_FEATURE_MATRIX!L12),IF(FULL_STACK_FEATURE_MATRIX!M12="",100,FULL_STACK_FEATURE_MATRIX!O12)) | G12: =IF(E12="P0",3,IF(E12="P1",2,1))
D13: =FULL_STACK_FEATURE_MATRIX!A13 | E13: =FULL_STACK_FEATURE_MATRIX!V13 | F13: =MIN(IF(FULL_STACK_FEATURE_MATRIX!F13="",0,FULL_STACK_FEATURE_MATRIX!F13),IF(FULL_STACK_FEATURE_MATRIX!G13="",100,FULL_STACK_FEATURE_MATRIX!I13),IF(FULL_STACK_FEATURE_MATRIX!J13="",100,FULL_STACK_FEATURE_MATRIX!L13),IF(FULL_STACK_FEATURE_MATRIX!M13="",100,FULL_STACK_FEATURE_MATRIX!O13)) | G13: =IF(E13="P0",3,IF(E13="P1",2,1))
D14: =FULL_STACK_FEATURE_MATRIX!A14 | E14: =FULL_STACK_FEATURE_MATRIX!V14 | F14: =MIN(IF(FULL_STACK_FEATURE_MATRIX!F14="",0,FULL_STACK_FEATURE_MATRIX!F14),IF(FULL_STACK_FEATURE_MATRIX!G14="",100,FULL_STACK_FEATURE_MATRIX!I14),IF(FULL_STACK_FEATURE_MATRIX!J14="",100,FULL_STACK_FEATURE_MATRIX!L14),IF(FULL_STACK_FEATURE_MATRIX!M14="",100,FULL_STACK_FEATURE_MATRIX!O14)) | G14: =IF(E14="P0",3,IF(E14="P1",2,1))
D15: =FULL_STACK_FEATURE_MATRIX!A15 | E15: =FULL_STACK_FEATURE_MATRIX!V15 | F15: =MIN(IF(FULL_STACK_FEATURE_MATRIX!F15="",0,FULL_STACK_FEATURE_MATRIX!F15),IF(FULL_STACK_FEATURE_MATRIX!G15="",100,FULL_STACK_FEATURE_MATRIX!I15),IF(FULL_STACK_FEATURE_MATRIX!J15="",100,FULL_STACK_FEATURE_MATRIX!L15),IF(FULL_STACK_FEATURE_MATRIX!M15="",100,FULL_STACK_FEATURE_MATRIX!O15)) | G15: =IF(E15="P0",3,IF(E15="P1",2,1))
D16: =FULL_STACK_FEATURE_MATRIX!A16 | E16: =FULL_STACK_FEATURE_MATRIX!V16 | F16: =MIN(IF(FULL_STACK_FEATURE_MATRIX!F16="",0,FULL_STACK_FEATURE_MATRIX!F16),IF(FULL_STACK_FEATURE_MATRIX!G16="",100,FULL_STACK_FEATURE_MATRIX!I16),IF(FULL_STACK_FEATURE_MATRIX!J16="",100,FULL_STACK_FEATURE_MATRIX!L16),IF(FULL_STACK_FEATURE_MATRIX!M16="",100,FULL_STACK_FEATURE_MATRIX!O16)) | G16: =IF(E16="P0",3,IF(E16="P1",2,1))
D17: =FULL_STACK_FEATURE_MATRIX!A17 | E17: =FULL_STACK_FEATURE_MATRIX!V17 | F17: =MIN(IF(FULL_STACK_FEATURE_MATRIX!F17="",0,FULL_STACK_FEATURE_MATRIX!F17),IF(FULL_STACK_FEATURE_MATRIX!G17="",100,FULL_STACK_FEATURE_MATRIX!I17),IF(FULL_STACK_FEATURE_MATRIX!J17="",100,FULL_STACK_FEATURE_MATRIX!L17),IF(FULL_STACK_FEATURE_MATRIX!M17="",100,FULL_STACK_FEATURE_MATRIX!O17)) | G17: =IF(E17="P0",3,IF(E17="P1",2,1))
D18: =FULL_STACK_FEATURE_MATRIX!A18 | E18: =FULL_STACK_FEATURE_MATRIX!V18 | F18: =MIN(IF(FULL_STACK_FEATURE_MATRIX!F18="",0,FULL_STACK_FEATURE_MATRIX!F18),IF(FULL_STACK_FEATURE_MATRIX!G18="",100,FULL_STACK_FEATURE_MATRIX!I18),IF(FULL_STACK_FEATURE_MATRIX!J18="",100,FULL_STACK_FEATURE_MATRIX!L18),IF(FULL_STACK_FEATURE_MATRIX!M18="",100,FULL_STACK_FEATURE_MATRIX!O18)) | G18: =IF(E18="P0",3,IF(E18="P1",2,1))
D19: =FULL_STACK_FEATURE_MATRIX!A19 | E19: =FULL_STACK_FEATURE_MATRIX!V19 | F19: =MIN(IF(FULL_STACK_FEATURE_MATRIX!F19="",0,FULL_STACK_FEATURE_MATRIX!F19),IF(FULL_STACK_FEATURE_MATRIX!G19="",100,FULL_STACK_FEATURE_MATRIX!I19),IF(FULL_STACK_FEATURE_MATRIX!J19="",100,FULL_STACK_FEATURE_MATRIX!L19),IF(FULL_STACK_FEATURE_MATRIX!M19="",100,FULL_STACK_FEATURE_MATRIX!O19)) | G19: =IF(E19="P0",3,IF(E19="P1",2,1))
D20: =FULL_STACK_FEATURE_MATRIX!A20 | E20: =FULL_STACK_FEATURE_MATRIX!V20 | F20: =MIN(IF(FULL_STACK_FEATURE_MATRIX!F20="",0,FULL_STACK_FEATURE_MATRIX!F20),IF(FULL_STACK_FEATURE_MATRIX!G20="",100,FULL_STACK_FEATURE_MATRIX!I20),IF(FULL_STACK_FEATURE_MATRIX!J20="",100,FULL_STACK_FEATURE_MATRIX!L20),IF(FULL_STACK_FEATURE_MATRIX!M20="",100,FULL_STACK_FEATURE_MATRIX!O20)) | G20: =IF(E20="P0",3,IF(E20="P1",2,1))
D21: =FULL_STACK_FEATURE_MATRIX!A21 | E21: =FULL_STACK_FEATURE_MATRIX!V21 | F21: =MIN(IF(FULL_STACK_FEATURE_MATRIX!F21="",0,FULL_STACK_FEATURE_MATRIX!F21),IF(FULL_STACK_FEATURE_MATRIX!G21="",100,FULL_STACK_FEATURE_MATRIX!I21),IF(FULL_STACK_FEATURE_MATRIX!J21="",100,FULL_STACK_FEATURE_MATRIX!L21),IF(FULL_STACK_FEATURE_MATRIX!M21="",100,FULL_STACK_FEATURE_MATRIX!O21)) | G21: =IF(E21="P0",3,IF(E21="P1",2,1))
D22: =FULL_STACK_FEATURE_MATRIX!A22 | E22: =FULL_STACK_FEATURE_MATRIX!V22 | F22: =MIN(IF(FULL_STACK_FEATURE_MATRIX!F22="",0,FULL_STACK_FEATURE_MATRIX!F22),IF(FULL_STACK_FEATURE_MATRIX!G22="",100,FULL_STACK_FEATURE_MATRIX!I22),IF(FULL_STACK_FEATURE_MATRIX!J22="",100,FULL_STACK_FEATURE_MATRIX!L22),IF(FULL_STACK_FEATURE_MATRIX!M22="",100,FULL_STACK_FEATURE_MATRIX!O22)) | G22: =IF(E22="P0",3,IF(E22="P1",2,1))
D23: =FULL_STACK_FEATURE_MATRIX!A23 | E23: =FULL_STACK_FEATURE_MATRIX!V23 | F23: =MIN(IF(FULL_STACK_FEATURE_MATRIX!F23="",0,FULL_STACK_FEATURE_MATRIX!F23),IF(FULL_STACK_FEATURE_MATRIX!G23="",100,FULL_STACK_FEATURE_MATRIX!I23),IF(FULL_STACK_FEATURE_MATRIX!J23="",100,FULL_STACK_FEATURE_MATRIX!L23),IF(FULL_STACK_FEATURE_MATRIX!M23="",100,FULL_STACK_FEATURE_MATRIX!O23)) | G23: =IF(E23="P0",3,IF(E23="P1",2,1))
... D45: =FULL_STACK_FEATURE_MATRIX!A45 | E45: =FULL_STACK_FEATURE_MATRIX!V45 | F45: =MIN(IF(FULL_STACK_FEATURE_MATRIX!F45="",0,FULL_STACK_FEATURE_MATRIX!F45),IF(FULL_STACK_FEATURE_MATRIX!G45="",100,FULL_STACK_FEATURE_MATRIX!I45),IF(FULL_STACK_FEATURE_MATRIX!J45="",100,FULL_STACK_FEATURE_MATRIX!L45),IF(FULL_STACK_FEATURE_MATRIX!M45="",100,FULL_STACK_FEATURE_MATRIX!O45)) | G45: =IF(E45="P0",3,IF(E45="P1",2,1))

Sheet GAP_ANALYSIS
A1: Feature_ID | B1: Feature_Name | C1: Missing_Layer | D1: Why_Missing | E1: Risk_Impact | F1: Must_Be_Done_Before_Production
A2: F-006 | B2: Subscription enforcement at gates (QR gen / offer create / redemption) | C2: Mobile | D2: Mobile Customer gap: Backend enforces subscription checks, but customer/merchant UIs do not gate or show clear expiry errors. | E2: Medium | F2: YES
A3: F-006 | B3: Subscription enforcement at gates (QR gen / offer create / redemption) | C3: Mobile | D3: Mobile Merchant gap: Backend enforces subscription checks, but customer/merchant UIs do not gate or show clear expiry errors. | E3: Medium | F3: YES
A4: F-006 | B4: Subscription enforcement at gates (QR gen / offer create / redemption) | C4: Web | D4: Web Admin gap: Backend enforces subscription checks, but customer/merchant UIs do not gate or show clear expiry errors. | E4: Medium | F4: YES
A5: F-007 | B5: Subscription payments (Stripe) enabled + deployed | C5: Backend | D5: Stripe disabled (STRIPE_ENABLED=0); no mobile payment UI; no payment method storage. | E5: High | F5: YES
A6: F-007 | B6: Subscription payments (Stripe) enabled + deployed | C6: Mobile | D6: Mobile Customer gap: Stripe disabled (STRIPE_ENABLED=0); no mobile payment UI; no payment method storage. | E6: High | F6: YES
A7: F-007 | B7: Subscription payments (Stripe) enabled + deployed | C7: Mobile | D7: Mobile Merchant gap: Stripe disabled (STRIPE_ENABLED=0); no mobile payment UI; no payment method storage. | E7: High | F7: YES
A8: F-007 | B8: Subscription payments (Stripe) enabled + deployed | C8: Web | D8: Web Admin gap: Stripe disabled (STRIPE_ENABLED=0); no mobile payment UI; no payment method storage. | E8: High | F8: YES
A9: F-008 | B9: Payment webhook handlers working in production | C9: Backend | D9: Webhook handlers exist but commented/unfinished; required IAM/permissions not granted. | E9: High | F9: YES
A10: F-009 | B10: Subscription auto-renewal (real charge, not simulated) | C10: Backend | D10: Auto-renewal scheduled but disabled; TODO payment processing; simulated success. | E10: High | F10: YES
A11: F-009 | B11: Subscription auto-renewal (real charge, not simulated) | C11: Web | D11: Web Admin gap: Auto-renewal scheduled but disabled; TODO payment processing; simulated success. | E11: High | F11: YES
A12: F-010 | B12: Cloud Scheduler enabled + scheduled jobs executing | C12: Backend | D12: Cloud Scheduler API not enabled; scheduled jobs not executing in production. | E12: High | F12: YES
... A76: F-043 | B76: Advanced analytics (cohort/ML) | C76: Web | D76: Web Admin gap: Only basic dashboard; advanced analytics absent. | E76: Low | F76: NO

Sheet EXECUTION_BACKLOG
A1: Task_ID | B1: Related_Feature_ID | C1: Task_Description | D1: Layer | E1: Depends_On | F1: Parallelizable (YES/NO) | G1: Status (Open/In Progress/Done) | H1: Output_Expected | I1: Created_At | J1: Updated_At
A2: T-0001 | B2: F-040 | C2: Set up Firebase/Google Secret Manager for QR_TOKEN_SECRET and Stripe keys; remove hardcoded/commented secret checks; add local emulator fallback for tests. | D2: Infra | F2: YES | G2: Open | H2: Secrets stored in Secret Manager; commented validations removed; security checks passing; evidence log in docs/evidence/runtime_secrets/<ts>/. | I2: 46030.158 | J2: 46030.158
A3: T-0002 | B3: F-010 | C3: Enable Cloud Scheduler API and ensure pubsub.schedule functions execute; add health-check function to report scheduler status. | D3: Infra | E3: T-0001 | F3: NO | G3: Open | H3: Scheduler running; scheduled functions produce logs; health-check endpoint returns OK; evidence in docs/evidence/runtime_scheduler/<ts>/. | I3: 46030.158 | J3: 46030.158
A4: T-0003 | B4: F-007 | C4: Implement minimal subscription purchase UI in Mobile Customer using Stripe (test mode) and wire to backend createCheckout/payment intent. | D4: Mobile | E4: T-0001 | F4: YES | G4: Open | H4: Customer can initiate subscription purchase; UI shows success/failure; unit tests pass; screenshot/log artifact. | I4: 46030.158 | J4: 46030.158
A5: T-0004 | B5: F-007 | C5: Implement minimal subscription purchase UI in Mobile Merchant (test mode) and wire to backend. | D5: Mobile | E5: T-0001 | F5: YES | G5: Open | H5: Merchant can initiate subscription purchase; success updates merchant subscription status; tests pass. | I5: 46030.158 | J5: 46030.158
A6: T-0005 | B6: F-007 | C6: Backend: implement subscription purchase endpoints (create customer, create subscription, store payment method reference) behind STRIPE_ENABLED flag; add emulator tests. | D6: Backend | E6: T-0001 | F6: NO | G6: Open | H6: Callable/HTTP functions for payment intent/subscription; tests in firebase-functions pass; no hardcoded secrets. | I6: 46030.158 | J6: 46030.158
A7: T-0006 | B7: F-008 | C7: Uncomment and complete payment webhook handlers; verify signature validation; update subscription status + record payments; add automated tests. | D7: Backend | E7: T-0001 | F7: NO | G7: Open | H7: Webhook endpoints active; tests for event types pass; updated data model docs; evidence logs. | I7: 46030.158 | J7: 46030.158
A8: T-0007 | B8: F-009 | C8: Replace simulated auto-renewal with real Stripe charge using saved payment method; integrate with scheduler; add failure notifications. | D8: Backend | E8: T-0002,T-0006 | F8: NO | G8: Open | H8: Auto-renewal executes on schedule; failures notify user; evidence logs. | I8: 46030.158 | J8: 46030.158
A9: T-0008 | B9: F-021 | C9: Wire phone + OTP authentication end-to-end in mobile apps; integrate sms.ts; add UI flows and tests. | D9: Mobile | F9: YES | G9: Open | H9: Customer & merchant can sign in via phone/OTP in emulator; flows covered by tests; evidence logs. | I9: 46030.158 | J9: 46030.158
A10: T-0009 | B10: F-022 | C10: Integrate Lebanese SMS gateway provider (Alfa/Touch/Ogero) or configurable adapter; update secrets/configs; add stub for testing. | D10: Backend/Infra | F10: YES | G10: Open | H10: SMS gateway adapter implemented; can switch providers via config; evidence logs. | I10: 46030.158 | J10: 46030.158
A11: T-0010 | B11: F-027 | C11: Create iOS signing/provisioning config and CI build step; ensure ios/ project builds in release. | D11: Mobile/Infra | F11: YES | G11: Open | H11: iOS release build succeeds; signing configured; build artifacts generated. | I11: 46030.158 | J11: 46030.158
A12: T-0011 | B12: F-028 | C12: Configure Android keystore + signing configs; ensure release APK/AAB builds. | D12: Mobile/Infra | F12: YES | G12: Open | H12: Android release build succeeds; signed artifact generated. | I12: 46030.158 | J12: 46030.158
A13: T-0012 | B13: F-011 | C13: Verify QR token cleanup job runs daily; add manual trigger + monitoring logs; write tests. | D13: Backend | E13: T-0002 | F13: YES | G13: Open | H13: Cleanup job executes; tokens older than 7 days soft-deleted; evidence logs. | I13: 46030.158 | J13: 46030.158
A14: T-0013 | B14: F-015 | C14: Implement merchant compliance (>=5 offers) enforcement in merchant UX and catalog gating; add warnings. | D14: Backend/Mobile | E14: T-0002 | F14: YES | G14: Open | H14: Merchants warned; offers hidden until compliant; tests + logs. | I14: 46030.158 | J14: 46030.158
A15: T-0014 | B15: F-016 | C15: Enable and verify subscription/offer expiry reminders; ensure scheduler executes; add templates. | D15: Backend | E15: T-0002 | F15: YES | G15: Open | H15: Reminders sent; logs + tests. | I15: 46030.158 | J15: 46030.158
A16: T-0015 | B16: F-023 | C16: Add i18n framework (Arabic+English) across mobile apps and web admin; start with key screens. | D16: Full Stack | F16: YES | G16: Open | H16: Localization works; Arabic strings loaded; tests for locale switch. | I16: 46030.158 | J16: 46030.158
A17: T-0016 | B17: F-031 | C17: Enable GDPR data export function and add UI entry point (web admin + mobile) with email delivery or download. | D17: Full Stack | F17: YES | G17: Open | H17: User can request export; data generated; audit trail recorded. | I17: 46030.158 | J17: 46030.158
A18: T-0017 | B18: F-032 | C18: Enable GDPR data deletion and add UI flow (confirm, delay window); ensure compliance logs. | D18: Full Stack | F18: YES | G18: Open | H18: Deletion request flow works; user data deleted; evidence logs. | I18: 46030.158 | J18: 46030.158
A19: T-0018 | B19: F-033 | C19: Configure production monitoring (Sentry/Datadog) for backend/web/mobile; add alerting defaults. | D19: Infra | F19: YES | G19: Open | H19: Errors captured; alerts configured; DSNs stored in secrets. | I19: 46030.158 | J19: 46030.158
A20: T-0019 | B20: F-034 | C20: Implement rate limiting for callable/HTTP functions; add tests. | D20: Backend | F20: YES | G20: Open | H20: Rate limits enforced; abuse tests pass. | I20: 46030.158 | J20: 46030.158
A21: T-0020 | B21: F-035 | C21: Enforce input validation across all functions; reject invalid payloads; add schema tests. | D21: Backend | F21: YES | G21: Open | H21: All endpoints validate inputs; tests pass. | I21: 46030.158 | J21: 46030.158
A22: T-0021 | B22: F-036 | C22: Implement audit logging collection + web admin viewer; log critical mutations and auth events. | D22: Full Stack | F22: YES | G22: Open | H22: Audit logs written; viewer shows searchable logs; tests pass. | I22: 46030.158 | J22: 46030.158
A23: T-0022 | B23: F-037 | C23: Automate Firestore backups (scheduled export) with retention and restore drill. | D23: Infra | F23: YES | G23: Open | H23: Backups run automatically; retention enforced; restore tested. | I23: 46030.158 | J23: 46030.158

Sheet TEST_CASES
A1: Test_ID | B1: Order_ID | C1: Related_Feature_ID | D1: Related_Task_ID | E1: Test_Level | F1: Test_Type | G1: Command | H1: Pass_Criteria | I1: Expected_Artifacts | J1: Must_Be_Done_Before_Production | K1: Priority | L1: Notes | M1: Last_Updated_At | N1: Last_Updated_By
A2: TC-0001 | C2: F-040 | D2: T-0001 | E2: E2E | F2: behavior | H2: Must pass with exit 0 and produce expected artifacts. | J2: NO | K2: P2 | L2: Set up Firebase/Google Secret Manager for QR_TOKEN_SECRET and Stripe keys; remove hardcoded/commented secret checks; add local emulator fallback for tests. | M2: 2026-01-10 18:13:11 | N2: ChatGPT
A3: TC-0002 | B3: ORD-12 | C3: F-010 | D3: T-0002 | E3: E2E | F3: behavior | H3: Must pass with exit 0 and produce expected artifacts. | J3: NO | K3: P2 | L3: Enable Cloud Scheduler API and ensure pubsub.schedule functions execute; add health-check function to report scheduler status. | M3: 2026-01-10 18:13:11 | N3: ChatGPT
A4: TC-0003 | B4: ORD-10 | C4: F-007 | D4: T-0003 | E4: E2E | F4: behavior | H4: Must pass with exit 0 and produce expected artifacts. | J4: NO | K4: P2 | L4: Implement minimal subscription purchase UI in Mobile Customer using Stripe (test mode) and wire to backend createCheckout/payment intent. | M4: 2026-01-10 18:13:11 | N4: ChatGPT
A5: TC-0004 | B5: ORD-10 | C5: F-007 | D5: T-0004 | E5: E2E | F5: behavior | H5: Must pass with exit 0 and produce expected artifacts. | J5: NO | K5: P2 | L5: Implement minimal subscription purchase UI in Mobile Merchant (test mode) and wire to backend. | M5: 2026-01-10 18:13:11 | N5: ChatGPT
A6: TC-0005 | B6: ORD-10 | C6: F-007 | D6: T-0005 | E6: E2E | F6: behavior | H6: Must pass with exit 0 and produce expected artifacts. | J6: NO | K6: P2 | L6: Backend: implement subscription purchase endpoints (create customer, create subscription, store payment method reference) behind STRIPE_ENABLED flag; add emulator tests. | M6: 2026-01-10 18:13:11 | N6: ChatGPT
A7: TC-0006 | B7: ORD-11 | C7: F-008 | D7: T-0006 | E7: E2E | F7: behavior | H7: Must pass with exit 0 and produce expected artifacts. | J7: NO | K7: P2 | L7: Uncomment and complete payment webhook handlers; verify signature validation; update subscription status + record payments; add automated tests. | M7: 2026-01-10 18:13:11 | N7: ChatGPT
A8: TC-0007 | B8: ORD-10 | C8: F-009 | D8: T-0007 | E8: E2E | F8: behavior | H8: Must pass with exit 0 and produce expected artifacts. | J8: NO | K8: P2 | L8: Replace simulated auto-renewal with real Stripe charge using saved payment method; integrate with scheduler; add failure notifications. | M8: 2026-01-10 18:13:11 | N8: ChatGPT
A9: TC-0008 | B9: ORD-01 | C9: F-021 | D9: T-0008 | E9: E2E | F9: behavior | H9: Must pass with exit 0 and produce expected artifacts. | J9: NO | K9: P2 | L9: Wire phone + OTP authentication end-to-end in mobile apps; integrate sms.ts; add UI flows and tests. | M9: 2026-01-10 18:13:11 | N9: ChatGPT
A10: TC-0009 | B10: ORD-01 | C10: F-022 | D10: T-0009 | E10: Integration | F10: behavior | H10: Must pass with exit 0 and produce expected artifacts. | J10: NO | K10: P2 | L10: Integrate Lebanese SMS gateway provider (Alfa/Touch/Ogero) or configurable adapter; update secrets/configs; add stub for testing. | M10: 2026-01-10 18:13:11 | N10: ChatGPT
A11: TC-0010 | B11: ORD-13 | C11: F-027 | D11: T-0010 | E11: Integration | F11: behavior | H11: Must pass with exit 0 and produce expected artifacts. | J11: NO | K11: P2 | L11: Create iOS signing/provisioning config and CI build step; ensure ios/ project builds in release. | M11: 2026-01-10 18:13:11 | N11: ChatGPT
A12: TC-0011 | B12: ORD-13 | C12: F-028 | D12: T-0011 | E12: Integration | F12: behavior | H12: Must pass with exit 0 and produce expected artifacts. | J12: NO | K12: P2 | L12: Configure Android keystore + signing configs; ensure release APK/AAB builds. | M12: 2026-01-10 18:13:11 | N12: ChatGPT
A13: TC-0012 | B13: ORD-04 | C13: F-011 | D13: T-0012 | E13: E2E | F13: behavior | H13: Must pass with exit 0 and produce expected artifacts. | J13: NO | K13: P2 | L13: Verify QR token cleanup job runs daily; add manual trigger + monitoring logs; write tests. | M13: 2026-01-10 18:13:11 | N13: ChatGPT
A14: TC-0013 | B14: ORD-06 | C14: F-015 | D14: T-0013 | E14: Integration | F14: behavior | H14: Must pass with exit 0 and produce expected artifacts. | J14: NO | K14: P2 | L14: Implement merchant compliance (>=5 offers) enforcement in merchant UX and catalog gating; add warnings. | M14: 2026-01-10 18:13:11 | N14: ChatGPT
A15: TC-0014 | B15: ORD-07 | C15: F-016 | D15: T-0014 | E15: E2E | F15: behavior | H15: Must pass with exit 0 and produce expected artifacts. | J15: NO | K15: P2 | L15: Enable and verify subscription/offer expiry reminders; ensure scheduler executes; add templates. | M15: 2026-01-10 18:13:11 | N15: ChatGPT
A16: TC-0015 | C16: F-023 | D16: T-0015 | E16: Integration | F16: behavior | H16: Must pass with exit 0 and produce expected artifacts. | J16: NO | K16: P2 | L16: Add i18n framework (Arabic+English) across mobile apps and web admin; start with key screens. | M16: 2026-01-10 18:13:11 | N16: ChatGPT
A17: TC-0016 | B17: ORD-07 | C17: F-031 | D17: T-0016 | E17: Integration | F17: behavior | H17: Must pass with exit 0 and produce expected artifacts. | J17: NO | K17: P2 | L17: Enable GDPR data export function and add UI entry point (web admin + mobile) with email delivery or download. | M17: 2026-01-10 18:13:11 | N17: ChatGPT
A18: TC-0017 | B18: ORD-07 | C18: F-032 | D18: T-0017 | E18: Integration | F18: behavior | H18: Must pass with exit 0 and produce expected artifacts. | J18: NO | K18: P2 | L18: Enable GDPR data deletion and add UI flow (confirm, delay window); ensure compliance logs. | M18: 2026-01-10 18:13:11 | N18: ChatGPT
A19: TC-0018 | B19: ORD-13 | C19: F-033 | D19: T-0018 | E19: E2E | F19: behavior | H19: Must pass with exit 0 and produce expected artifacts. | J19: NO | K19: P2 | L19: Configure production monitoring (Sentry/Datadog) for backend/web/mobile; add alerting defaults. | M19: 2026-01-10 18:13:11 | N19: ChatGPT
